Error in database_auth function:
Traceback (most recent call last):
  File "/Users/dintal/Desktop/DockContainer/OptionsAnalysisWeb/Modules/DataBaseAuth.py", line 32, in login_control
    con,cur = connect_data_base()
              ^^^^^^^^^^^^^^^^^^^
  File "/Users/dintal/Desktop/DockContainer/OptionsAnalysisWeb/Modules/DataBaseAuth.py", line 20, in connect_data_base
    con = psycopg2.connect(database=SQL_DB, user=SQL_USER, password=SQL_PASSWORD, host=SQL_HOST)
          ^^^^^^^^^^^^^^^^^^^^^^^^^^^^^^^^^^^^^^^^^^^^^^^^^^^^^^^^^^^^^^^^^^^^^^^^^^^^^^^^^^^^^^
  File "/Users/dintal/anaconda3/envs/FinTech/lib/python3.11/site-packages/psycopg2/__init__.py", line 122, in connect
    conn = _connect(dsn, connection_factory=connection_factory, **kwasync)
           ^^^^^^^^^^^^^^^^^^^^^^^^^^^^^^^^^^^^^^^^^^^^^^^^^^^^^^^^^^^^^^^
psycopg2.OperationalError: connection to server at "192.168.123.86", port 5432 failed: Host is down
	Is the server running on that host and accepting TCP/IP connections?


Error in database_auth function:
Traceback (most recent call last):
  File "/Users/dintal/Desktop/DockContainer/OptionsAnalysisWeb/Modules/DataBaseAuth.py", line 32, in login_control
    con,cur = connect_data_base()
              ^^^^^^^^^^^^^^^^^^^
  File "/Users/dintal/Desktop/DockContainer/OptionsAnalysisWeb/Modules/DataBaseAuth.py", line 20, in connect_data_base
    con = psycopg2.connect(database=SQL_DB, user=SQL_USER, password=SQL_PASSWORD, host=SQL_HOST)
          ^^^^^^^^^^^^^^^^^^^^^^^^^^^^^^^^^^^^^^^^^^^^^^^^^^^^^^^^^^^^^^^^^^^^^^^^^^^^^^^^^^^^^^
  File "/Users/dintal/anaconda3/envs/FinTech/lib/python3.11/site-packages/psycopg2/__init__.py", line 122, in connect
    conn = _connect(dsn, connection_factory=connection_factory, **kwasync)
           ^^^^^^^^^^^^^^^^^^^^^^^^^^^^^^^^^^^^^^^^^^^^^^^^^^^^^^^^^^^^^^^
psycopg2.OperationalError: connection to server at "192.168.123.86", port 5432 failed: Host is down
	Is the server running on that host and accepting TCP/IP connections?


Error in database_auth function:
Traceback (most recent call last):
  File "/Users/dintal/Desktop/DockContainer/OptionsAnalysisWeb/Modules/DataBaseAuth.py", line 32, in login_control
    con,cur = connect_data_base()
              ^^^^^^^^^^^^^^^^^^^
  File "/Users/dintal/Desktop/DockContainer/OptionsAnalysisWeb/Modules/DataBaseAuth.py", line 20, in connect_data_base
    con = psycopg2.connect(database=SQL_DB, user=SQL_USER, password=SQL_PASSWORD, host=SQL_HOST)
          ^^^^^^^^^^^^^^^^^^^^^^^^^^^^^^^^^^^^^^^^^^^^^^^^^^^^^^^^^^^^^^^^^^^^^^^^^^^^^^^^^^^^^^
  File "/Users/dintal/anaconda3/envs/FinTech/lib/python3.11/site-packages/psycopg2/__init__.py", line 122, in connect
    conn = _connect(dsn, connection_factory=connection_factory, **kwasync)
           ^^^^^^^^^^^^^^^^^^^^^^^^^^^^^^^^^^^^^^^^^^^^^^^^^^^^^^^^^^^^^^^
psycopg2.OperationalError: connection to server at "192.168.123.86", port 5432 failed: Host is down
	Is the server running on that host and accepting TCP/IP connections?


Error in database_auth function:
Traceback (most recent call last):
  File "/Users/dintal/Desktop/DockContainer/OptionsAnalysisWeb/Modules/DataBaseAuth.py", line 32, in login_control
    con,cur = connect_data_base()
              ^^^^^^^^^^^^^^^^^^^
  File "/Users/dintal/Desktop/DockContainer/OptionsAnalysisWeb/Modules/DataBaseAuth.py", line 20, in connect_data_base
    con = psycopg2.connect(database=SQL_DB, user=SQL_USER, password=SQL_PASSWORD, host=SQL_HOST)
          ^^^^^^^^^^^^^^^^^^^^^^^^^^^^^^^^^^^^^^^^^^^^^^^^^^^^^^^^^^^^^^^^^^^^^^^^^^^^^^^^^^^^^^
  File "/Users/dintal/anaconda3/envs/FinTech/lib/python3.11/site-packages/psycopg2/__init__.py", line 122, in connect
    conn = _connect(dsn, connection_factory=connection_factory, **kwasync)
           ^^^^^^^^^^^^^^^^^^^^^^^^^^^^^^^^^^^^^^^^^^^^^^^^^^^^^^^^^^^^^^^
psycopg2.OperationalError: connection to server at "192.168.123.86", port 5432 failed: Host is down
	Is the server running on that host and accepting TCP/IP connections?


Error in database_auth function:
Traceback (most recent call last):
  File "/Users/dintal/Desktop/DockContainer/OptionsAnalysisWeb/Modules/DataBaseAuth.py", line 32, in login_control
    con,cur = connect_data_base()
              ^^^^^^^^^^^^^^^^^^^
  File "/Users/dintal/Desktop/DockContainer/OptionsAnalysisWeb/Modules/DataBaseAuth.py", line 20, in connect_data_base
    con = psycopg2.connect(database=SQL_DB, user=SQL_USER, password=SQL_PASSWORD, host=SQL_HOST)
          ^^^^^^^^^^^^^^^^^^^^^^^^^^^^^^^^^^^^^^^^^^^^^^^^^^^^^^^^^^^^^^^^^^^^^^^^^^^^^^^^^^^^^^
  File "/Users/dintal/anaconda3/envs/FinTech/lib/python3.11/site-packages/psycopg2/__init__.py", line 122, in connect
    conn = _connect(dsn, connection_factory=connection_factory, **kwasync)
           ^^^^^^^^^^^^^^^^^^^^^^^^^^^^^^^^^^^^^^^^^^^^^^^^^^^^^^^^^^^^^^^
psycopg2.OperationalError: connection to server at "192.168.123.86", port 5432 failed: Host is down
	Is the server running on that host and accepting TCP/IP connections?


Error in database_auth function:
Traceback (most recent call last):
  File "/Users/dintal/Desktop/DockContainer/OptionsAnalysisWeb/Modules/DataBaseAuth.py", line 32, in login_control
    con,cur = connect_data_base()
              ^^^^^^^^^^^^^^^^^^^
  File "/Users/dintal/Desktop/DockContainer/OptionsAnalysisWeb/Modules/DataBaseAuth.py", line 20, in connect_data_base
    con = psycopg2.connect(database=SQL_DB, user=SQL_USER, password=SQL_PASSWORD, host=SQL_HOST)
          ^^^^^^^^^^^^^^^^^^^^^^^^^^^^^^^^^^^^^^^^^^^^^^^^^^^^^^^^^^^^^^^^^^^^^^^^^^^^^^^^^^^^^^
  File "/Users/dintal/anaconda3/envs/FinTech/lib/python3.11/site-packages/psycopg2/__init__.py", line 122, in connect
    conn = _connect(dsn, connection_factory=connection_factory, **kwasync)
           ^^^^^^^^^^^^^^^^^^^^^^^^^^^^^^^^^^^^^^^^^^^^^^^^^^^^^^^^^^^^^^^
psycopg2.OperationalError: connection to server at "192.168.123.86", port 5432 failed: Host is down
	Is the server running on that host and accepting TCP/IP connections?


Error in database_auth function:
Traceback (most recent call last):
  File "/Users/dintal/Desktop/DockContainer/OptionsAnalysisWeb/Modules/DataBaseAuth.py", line 32, in login_control
    con,cur = connect_data_base()
              ^^^^^^^^^^^^^^^^^^^
  File "/Users/dintal/Desktop/DockContainer/OptionsAnalysisWeb/Modules/DataBaseAuth.py", line 20, in connect_data_base
    con = psycopg2.connect(database=SQL_DB, user=SQL_USER, password=SQL_PASSWORD, host=SQL_HOST)
          ^^^^^^^^^^^^^^^^^^^^^^^^^^^^^^^^^^^^^^^^^^^^^^^^^^^^^^^^^^^^^^^^^^^^^^^^^^^^^^^^^^^^^^
  File "/Users/dintal/anaconda3/envs/FinTech/lib/python3.11/site-packages/psycopg2/__init__.py", line 122, in connect
    conn = _connect(dsn, connection_factory=connection_factory, **kwasync)
           ^^^^^^^^^^^^^^^^^^^^^^^^^^^^^^^^^^^^^^^^^^^^^^^^^^^^^^^^^^^^^^^
psycopg2.OperationalError: connection to server at "192.168.123.86", port 5432 failed: Host is down
	Is the server running on that host and accepting TCP/IP connections?


Error in database_auth function:
Traceback (most recent call last):
  File "/Users/dintal/Desktop/DockContainer/OptionsAnalysisWeb/Modules/DataBaseAuth.py", line 32, in login_control
    con,cur = connect_data_base()
              ^^^^^^^^^^^^^^^^^^^
  File "/Users/dintal/Desktop/DockContainer/OptionsAnalysisWeb/Modules/DataBaseAuth.py", line 20, in connect_data_base
    con = psycopg2.connect(database=SQL_DB, user=SQL_USER, password=SQL_PASSWORD, host=SQL_HOST)
          ^^^^^^^^^^^^^^^^^^^^^^^^^^^^^^^^^^^^^^^^^^^^^^^^^^^^^^^^^^^^^^^^^^^^^^^^^^^^^^^^^^^^^^
  File "/Users/dintal/anaconda3/envs/FinTech/lib/python3.11/site-packages/psycopg2/__init__.py", line 122, in connect
    conn = _connect(dsn, connection_factory=connection_factory, **kwasync)
           ^^^^^^^^^^^^^^^^^^^^^^^^^^^^^^^^^^^^^^^^^^^^^^^^^^^^^^^^^^^^^^^
psycopg2.OperationalError: connection to server at "192.168.123.86", port 5432 failed: Host is down
	Is the server running on that host and accepting TCP/IP connections?


